Workbook

Sheet 引张线
A1: 部位 | B1: 库水位m | C1: 1号坝段 | D1: 2号坝段 | E1: 3号坝段 | F1: 4号坝段 | G1: 4号坝段 | H1: 5号坝段 | I1: 5号坝段 | J1: 6号坝段 | K1: 7号坝段 | L1: 8号坝段 | M1: 9号坝段 | N1: 10号坝段 | P1: 3号坝段 | Q1: 4号坝段 | R1: 5号坝段 | S1: 6号坝段 | T1: 7号坝段 | U1: 8号坝段 | X1: 4号坝段 | Y1: 5号坝段 | Z1: 6号坝段 | AA1: 7号坝段
A2: 平面位置(m) | D2: 坝左0+150.000 | E2: 坝左0+090.000 | F2: 坝左0+037.500 | G2: 坝左0+022.500 | H2: 坝右0+022.500 | I2: 坝右0+037.000 | J2: 坝右0+090.000 | K2: 坝右0+150.000 | L2: 坝右0+210.000 | M2: 坝右0+270.000 | P2: 坝左0+090.00 | Q2: 坝左0+030.00 | R2: 坝右0+030.00 | S2: 坝右0+090.00 | T2: 坝右0+150.00 | U2: 坝右0+210.00 | X2: 坝左0+030.00 | Y2: 坝右0+030.00 | Z2: 坝右0+090.00 | AA2: 坝右0+150.00
C3: -199.6 | D3: -150 | E3: -90 | F3: -37.5 | G3: -22.5 | H3: 22.5 | I3: 37 | J3: 90 | K3: 150 | L3: 210 | M3: 270 | N3: 323 | O3: -161.8 | P3: -90 | Q3: -30 | R3: 30 | S3: 90 | T3: 150 | U3: 210 | V3: 257 | W3: -109.6 | X3: -30 | Y3: 30 | Z3: 90 | AA3: 150 | AB3: 177.65
A4: 高程(m) | C4: 153 | O4: 120 | W4: 88
A5: 埋设时间 | D5: 43230 | E5: 43230 | F5: 43230 | G5: 43230 | H5: 43230 | I5: 43230 | J5: 43230 | K5: 43230 | L5: 43230 | M5: 43230 | N5: IP2 | O5: IP3 | P5: 43230 | Q5: 43230 | R5: 43230 | S5: 43230 | T5: 43230 | U5: 43230 | V5: IP4 | W5: IP5 | X5: 43230 | Y5: 43230 | Z5: 43230 | AA5: 43230 | AB5: IP6
A6: 仪器编号 | C6: IP1 | D6: EX1-2 | E6: EX1-3 | F6: EX1-4 | G6: EX1-5 | H6: EX1-6 | I6: EX1-7 | J6: EX1-8 | K6: EX1-9 | L6: EX1-10 | M6: EX1-11 | P6: EX2-2 | Q6: EX2-3 | R6: EX2-4 | S6: EX2-5 | T6: EX2-6 | U6: EX2-7 | X6: EX3-2 | Y6: EX3-3 | Z6: EX3-4 | AA6: EX3-4′
A7: 观测时间 | D7: 位移mm | E7: 位移mm | F7: 位移mm | G7: 位移mm | H7: 位移mm | I7: 位移mm | J7: 位移mm | K7: 位移mm | L7: 位移mm | M7: 位移mm | P7: 位移mm | Q7: 位移mm | R7: 位移mm | S7: 位移mm | T7: 位移mm | U7: 位移mm | X7: 位移mm | Y7: 位移mm | Z7: 位移mm | AA7: 位移mm
A8: 43258 | B8: 138.6 | C8: 0 | D8: 0 | E8: 0 | F8: 0 | G8: 0 | H8: 0 | I8: 0 | J8: 0 | K8: 0 | L8: 0 | M8: 0 | N8: 0 | O8: 0 | P8: 0 | Q8: 0 | R8: 0 | S8: 0 | T8: 0 | U8: 0 | V8: 0 | W8: 0 | X8: 0 | Y8: 0 | Z8: 0 | AA8: 0 | AB8: 0
A9: 43262 | B9: 141.9 | C9: 0.27 | D9: 0.48678357 | E9: 2.0991862 | F9: 2.4520587 | G9: 2.3400632 | H9: 1.9816328 | I9: 2.0585175 | J9: 1.424265 | K9: 1.0423394 | L9: 0.97418907 | M9: 0.72049471 | N9: 0.16 | O9: 0.12 | P9: 1.1375227 | Q9: 1.4904338 | R9: 1.2910085 | S9: 1.1171967 | T9: 0.91389886 | U9: 0.73694297 | V9: 0.51 | W9: 0.16 | X9: -2.0723432 | Y9: -1.6516374 | Z9: 0.10992829 | AA9: 0.12541738 | AB9: 0.05
A10: 43263 | B10: 142.22 | C10: 0.29 | D10: 0.68612485 | E10: 2.3553072 | F10: 2.6608294 | G10: 2.5417567 | H10: 2.1843175 | I10: 2.2744909 | J10: 1.6290569 | K10: 1.2420787 | L10: 1.1888538 | M10: 0.87481887 | N10: 0.23 | O10: 0.21 | P10: 1.2638332 | Q10: 1.5848988 | R10: 1.4348774 | S10: 1.2891704 | T10: 1.1174795 | U10: 0.88687636 | V10: 0.57 | W10: 0.21 | X10: -2.0027294 | Y10: -1.5691738 | Z10: 0.18697383 | AA10: 0.23612485 | AB10: 0.16
A11: 43265 | B11: 141.86 | C11: 0.28 | D11: 0.72887159 | E11: 2.1704075 | F11: 2.5925573 | G11: 2.4578084 | H11: 2.1343822 | I11: 2.2362637 | J11: 1.4685308 | K11: 1.0077862 | L11: 0.93001253 | M11: 0.71824072 | N11: 0.19 | O11: 0.12 | P11: 1.3141434 | Q11: 1.7211705 | R11: 1.4299123 | S11: 1.1577661 | T11: 0.90917416 | U11: 0.74455133 | V11: 0.64 | W11: 0.24 | X11: -2.0356403 | Y11: -1.5990479 | Z11: 0.091490108 | AA11: 0.080567819 | AB11: 0.06
A12: 43267 | B12: 141.16 | C12: 0.29 | D12: 0.57437166 | E12: 2.2636181 | F12: 2.8029917 | G12: 2.6903835 | H12: 2.287689 | I12: 2.3262882 | J12: 1.6128197 | K12: 1.1460786 | L12: 0.95824569 | M12: 0.69539979 | N12: 0.15 | O12: 0.14 | P12: 1.2299864 | Q12: 1.6499376 | R12: 1.450103 | S12: 1.2246659 | T12: 1.0523496 | U12: 0.79128377 | V12: 0.6 | W12: 0.27 | X12: -1.9909641 | Y12: -1.4763247 | Z12: 0.18763925 | AA12: 0.24612918 | AB12: 0.24
A13: 43269 | B13: 143.96 | C13: 0.08 | D13: 0.85781498 | E13: 2.8650072 | F13: 3.1123399 | G13: 3.0443557 | H13: 2.717139 | I13: 2.7455711 | J13: 2.1628691 | K13: 1.8531256 | L13: 1.9182626 | M13: 1.5047079 | N13: 0.34 | O13: 0.11 | P13: 1.6376986 | Q13: 2.0315539 | R13: 1.9896519 | S13: 1.9266124 | T13: 1.8396759 | U13: 1.4664665 | V13: 1 | W13: 0.43 | X13: -1.7899629 | Y13: -1.3616195 | Z13: 0.24885981 | AA13: 0.2995477 | AB13: 0.3
A14: 43272 | B14: 145.53 | C14: 0.76 | D14: 1.8863284 | E14: 3.9561818 | F14: 3.9628873 | G14: 3.8605844 | H14: 3.365112 | I14: 3.3271266 | J14: 2.5531518 | K14: 2.1023946 | L14: 2.4070119 | M14: 2.1097654 | N14: 0.58 | O14: 0.22 | P14: 2.1912825 | Q14: 2.5559548 | R14: 2.4989784 | S14: 2.3042745 | T14: 2.0808388 | U14: 1.9342669 | V14: 1.66 | W14: 0.66 | X14: -1.6373079 | Y14: -1.3108591 | Z14: 0.18299712 | AA14: 0.12473123 | AB14: 0.1
A15: 43273 | B15: 145.16 | C15: 0.68 | D15: 1.9006169 | E15: 3.9688929 | F15: 4.0802617 | G15: 3.9957685 | H15: 3.5098038 | I15: 3.5305494 | J15: 2.7443109 | K15: 2.2772988 | L15: 2.4885725 | M15: 2.1235911 | N15: 0.53 | O15: 0.12 | P15: 2.1316734 | Q15: 2.5362928 | R15: 2.5264926 | S15: 2.3937587 | T15: 2.2466594 | U15: 2.0084065 | V15: 1.69 | W15: 0.64 | X15: -1.6151243 | Y15: -1.2078061 | Z15: 0.22062885 | AA15: 0.044722183 | AB15: 0.34
A16: 43274 | B16: 144.88 | C16: 0.47 | D16: 1.4413407 | E16: 3.3346462 | F16: 3.6722859 | G16: 3.6576265 | H16: 3.2563251 | I16: 3.5071124 | J16: 2.3872937 | K16: 1.9940665 | L16: 2.1520496 | M16: 1.7030446 | N16: 0.34 | O16: 0.07 | P16: 2.0044351 | Q16: 2.3710506 | R16: 2.3208475 | S16: 2.1539582 | T16: 1.9984232 | U16: 1.7741535 | V16: 1.49 | W16: 0.58 | X16: -1.6821772 | Y16: -1.2435067 | Z16: 0.16900692 | AA16: 0.026667542 | AB16: 0.33
A17: 43277 | B17: 144.13 | C17: 0.43 | D17: 0.9225592 | E17: 2.9901 | F17: 3.399053 | G17: 3.3700438 | H17: 3.1207181 | I17: 3.188109 | J17: 2.3149411 | K17: 2.0488411 | L17: 2.149349 | M17: 1.6588793 | N17: 0.36 | O17: 0.21 | P17: 2.0399164 | Q17: 2.3735333 | R17: 2.286312 | S17: 2.120589 | T17: 1.9722203 | U17: 1.6955148 | V17: 1.49 | W17: 0.6 | X17: -1.6451187 | Y17: -1.2404107 | Z17: 0.21094254 | AA17: 0.063366543 | AB17: 0.39
A18: 43279 | B18: 143.58 | C18: 0.29 | D18: 0.56660084 | E18: 2.5550744 | F18: 3.041378 | G18: 3.1281758 | H18: 2.7899104 | I18: 2.8661416 | J18: 1.9704438 | K18: 1.7282271 | L18: 1.7956245 | M18: 2.4015536 | N18: 0.2 | O18: 0.16 | P18: 1.8644973 | Q18: 2.276406 | R18: 2.1482439 | S18: 1.949826 | T18: 1.8245633 | U18: 1.449911 | V18: 1.4 | W18: 0.55 | X18: -1.6577999 | Y18: -1.2563916 | Z18: 0.21251259 | AA18: 0.099320964 | AB18: 0.41
A19: 43281 | B19: 142.72 | C19: 0.14 | D19: 0.14248963 | E19: 1.9816235 | F19: 2.5005439 | G19: 2.7152295 | H19: 2.3242336 | I19: 2.4213777 | J19: 1.545403 | K19: 1.3753597 | L19: 1.434139 | M19: 2.4947272 | N19: 0.04 | O19: 0.11 | P19: 1.5774746 | Q19: 2.0120096 | R19: 1.8906485 | S19: 1.7072775 | T19: 1.6528623 | U19: 1.1943066 | V19: 1.3 | W19: 0.5 | X19: -1.6704828 | Y19: -1.2723725 | Z19: 0.21408264 | AA19: 0.13527508 | AB19: 0.43
... A24: 43295 | B24: 148.69 | C24: 1.12 | D24: 4.0183128 | E24: 7.6588122 | F24: 8.1166675 | G24: 8.195767 | H24: 7.8979674 | I24: 7.8948654 | J24: 7.3620709 | K24: 7.4287418 | L24: 7.5576795 | M24: 7.1154354 | N24: 0.97 | O24: 0.58 | P24: 4.1168376 | Q24: 4.7815583 | R24: 4.8138251 | S24: 4.1734735 | T24: 4.8178966 | U24: 3.5894129 | V24: 2.94 | W24: 1.11 | X24: -1.8297109 | Y24: 0.72661341 | Z24: 1.8964565 | AA24: 0.39512333 | AB24: 1.04
A25: 43298 | B25: 148.88 | C25: 1.21 | D25: 4.4415939 | E25: 8.3978586 | F25: 8.9799895 | G25: 9.0006842 | H25: 8.5952625 | I25: 8.5444943 | J25: 7.9390586 | K25: 7.9306667 | L25: 8.0595069 | M25: 7.5125102 | N25: 1.06 | O25: 0.67 | P25: 4.5338867 | Q25: 5.3020427 | R25: 5.293422 | S25: 4.6118793 | T25: 5.1966937 | U25: 4.0657375 | V25: 3.16
A26: 43300 | B26: 148.37 | C26: 1.11 | D26: 4.2698753 | E26: 8.2357296 | F26: 8.9548372 | G26: 8.9289011 | H26: 8.5580781 | I26: 8.5590456 | J26: 7.815259 | K26: 7.8819058 | L26: 8.0264108 | M26: 7.5357088 | N26: 1.07 | O26: 0.74 | P26: 4.5059012 | Q26: 5.2137046 | R26: 5.2692753 | S26: 4.5346211 | T26: 5.1531195 | U26: 4.1276024 | V26: 3.13
A27: 43305 | B27: 148.18 | C27: 0.85 | D27: 3.7928533 | E27: 7.5269348 | F27: 8.2936775 | G27: 8.3745148 | H27: 8.1416672 | I27: 8.2512719 | J27: 7.3456915 | K27: 7.4026973 | L27: 7.5336457 | M27: 7.0192717 | N27: 0.88 | O27: 0.82 | P27: 4.3295477 | Q27: 4.8219536 | R27: 5.1090296 | S27: 4.4705419 | T27: 5.2230125 | U27: 4.7698358 | V27: 3.04
A28: 43308 | B28: 148.32 | C28: 0.92 | D28: 3.9752421 | E28: 7.8118451 | F28: 8.5316783 | G28: 8.6554971 | H28: 8.39473 | I28: 8.4384063 | J28: 7.6451715 | K28: 7.6407375 | L28: 7.7843482 | M28: 7.2417902 | N28: 0.95 | O28: 0.9 | P28: 4.5294936 | Q28: 5.2085784 | R28: 5.3041291 | S28: 4.6636034 | T28: 5.4268976 | U28: 4.9089297 | V28: 3.18
A29: 43312 | B29: 147.51 | C29: 0.89 | D29: 3.656744 | E29: 7.2468243 | F29: 7.988628 | G29: 8.1524967 | H29: 7.8449799 | I29: 7.7838724 | J29: 7.0263208 | K29: 7.0357329 | L29: 7.2337892 | M29: 6.8592013 | N29: 0.88 | O29: 0.88 | P29: 4.25384 | Q29: 4.8828806 | R29: 4.9908144 | S29: 4.4073398 | T29: 5.1944412 | U29: 4.5787876 | V29: 3 | W29: 0 | X29: -1.83 | Y29: 0.73 | Z29: 1.9 | AA29: 0.4 | AB29: 0
A30: 43314 | B30: 147.1 | C30: 0.78 | D30: 3.2784988 | E30: 6.6508136 | F30: 7.2911547 | G30: 7.4925273 | H30: 7.2191733 | I30: 7.4294164 | J30: 6.3537215 | K30: 6.3917661 | L30: 6.5897597 | M30: 6.4074536 | N30: 0.79 | O30: 0.76 | P30: 4.0472103 | Q30: 4.4440224 | R30: 4.400609 | S30: 4.174976 | T30: 5.06563 | U30: 4.3906788 | V30: 2.84 | W30: -0.1 | X30: -1.9005104 | Y30: 0.70116644 | Z30: 1.8467343 | AA30: 0.45108168 | AB30: 0.06
A31: 43319 | B31: 146.89 | C31: 0.88 | D31: 3.3920608 | E31: 6.7977817 | F31: 7.484013 | G31: 7.6602668 | H31: 7.2974744 | I31: 7.3325055 | J31: 6.5048904 | K31: 6.4972242 | L31: 6.6717508 | M31: 6.4548914 | N31: 0.82 | O31: 0.65 | P31: 3.9503121 | Q31: 4.4060783 | R31: 4.476274 | S31: 4.218983 | T31: 5.1798446 | U31: 4.3947893 | V31: 2.81 | W31: -0.03 | X31: -1.8303119 | Y31: 0.72016522 | Z31: 1.8394822 | AA31: 0.54445875 | AB31: 0.12
A32: 43321 | B32: 147.69 | C32: 0.98 | D32: 3.8543878 | E32: 7.868954 | F32: 8.3112982 | G32: 8.4793445 | H32: 8.1511021 | I32: 8.1934828 | J32: 7.3814781 | K32: 7.3808886 | L32: 7.4504873 | M32: 6.9474235 | N32: 0.9 | O32: 0.53 | P32: 4.2721481 | Q32: 4.9049187 | R32: 4.9394311 | S32: 4.6667717 | T32: 5.5516308 | U32: 4.7103068 | V32: 3.01 | W32: 0.01 | X32: -1.7164684 | Y32: 0.83909696 | Z32: 1.9519658 | AA32: 0.6835703 | AB32: 0.18
A33: 43326 | B33: 148.89 | C33: 1.3 | D33: 4.874174 | E33: 9.3070037 | F33: 9.7168947 | G33: 9.860408 | H33: 9.5056532 | I33: 9.5448082 | J33: 8.6732718 | K33: 8.6464893 | L33: 8.8201507 | M33: 8.0961445 | N33: 1.34 | O33: 0.56 | P33: 4.8295744 | Q33: 5.5948589 | R33: 5.5846411 | S33: 5.2102022 | T33: 5.9067164 | U33: 5.2430931 | V33: 3.43 | W33: 0.13 | X33: -1.5093456 | Y33: 0.98714086 | Z33: 2.0677396 | AA33: 0.69089372 | AB33: 0.1
A34: 43328 | B34: 148.63 | C34: 1.28 | D34: 4.7738436 | E34: 9.1958907 | F34: 9.6180795 | G34: 9.7646412 | H34: 9.4080295 | I34: 9.4322865 | J34: 8.5965699 | K34: 8.5872156 | L34: 8.7147603 | M34: 7.9192079 | N34: 1.13 | O34: 0.3 | P34: 4.7121823 | Q34: 5.5432995 | R34: 5.56887 | S34: 5.2115379 | T34: 5.9073979 | U34: 5.2924379 | V34: 3.51 | W34: 0.18 | X34: -1.4763695 | Y34: 1.0078138 | Z34: 2.0782278 | AA34: 0.71122714 | AB34: 0.11
A35: 43333 | B35: 148.74 | C35: 1.14 | D35: 4.6859135 | E35: 9.2752601 | F35: 9.8592157 | G35: 10.032337 | H35: 9.696481 | I35: 9.4655807 | J35: 8.7846615 | K35: 8.7773195 | L35: 8.852809 | M35: 8.0352608 | N35: 1.07 | O35: 0.27 | P35: 4.7620918 | Q35: 5.6561532 | R35: 5.6792542 | S35: 5.341543 | T35: 5.9771854 | U35: 5.3266523 | V35: 3.33 | W35: 0.21 | X35: -1.4342918 | Y35: 1.0758002 | Z35: 2.186229 | AA35: 0.79378008 | AB35: 0.13
A36: 43335 | B36: 148.28 | C36: 1.14 | D36: 4.5375653 | E36: 9.0032733 | F36: 9.5561111 | G36: 9.7478112 | H36: 9.437675 | I36: 9.2716151 | J36: 8.5528307 | K36: 8.5480486 | L36: 8.6460785 | M36: 7.9274247 | N36: 1.05 | O36: 0.25 | P36: 4.6311806 | Q36: 5.5174169 | R36: 5.5619408 | S36: 5.2403093 | T36: 5.95734 | U36: 5.3065826 | V36: 3.28 | W36: 0.19 | X36: -1.4608273 | Y36: 1.0308294 | Z36: 2.1431352 | AA36: 0.79116745 | AB36: 0.14
A37: 43342 | B37: 147.88 | C37: 0.9 | D37: 4.0327421 | E37: 8.2644743 | F37: 8.7802374 | G37: 8.9967555 | H37: 8.7981348 | I37: 8.5807135 | J37: 7.8796884 | K37: 7.9276509 | L37: 8.1105455 | M37: 7.4621293 | N37: 0.88 | O37: 0.53 | P37: 4.6034817 | Q37: 5.2647584 | R37: 5.3096649 | S37: 5.0185347 | T37: 5.8444288 | U37: 4.6483948 | V37: 3.3 | W37: 0.02 | X37: -1.6344024 | Y37: 0.85931974 | Z37: 2.016191 | AA37: 0.88757587 | AB37: 0.15
A38: 43349 | B38: 144.21 | C38: 0.34 | D38: 2.0833189 | E38: 5.1847508 | F38: 5.7921047 | G38: 6.0650255 | H38: 5.9216758 | I38: 6.3758117 | J38: 4.979223 | K38: 5.065661 | L38: 5.123506 | M38: 5.0993734 | N38: 0.32 | O38: 0.81 | P38: 3.4273707 | Q38: 3.6748034 | R38: 3.8175466 | S38: 3.6443492 | T38: 4.6362357 | U38: 3.8617965 | V38: 2.34 | W38: -0.24 | X38: -2.1345642 | Y38: 0.30362958 | Z38: 1.6197306 | AA38: 0.75095608 | AB38: 0.17
A39: 43356 | B39: 141.86 | C39: 0.29 | D39: 0.93605544 | E39: 3.3479824 | F39: 3.7647204 | G39: 4.0802165 | H39: 3.9258054 | I39: 4.1472805 | J39: 3.0214538 | K39: 3.01004 | L39: 3.1697321 | M39: 3.7781049 | N39: 0.17 | O39: 1.1 | P39: 2.6402698 | Q39: 2.5544072 | R39: 2.7798501 | S39: 2.6793565 | T39: 3.8586265 | U39: 3.0443569 | V39: 1.62 | W39: -0.49 | X39: -2.5560527 | Y39: -0.12000597 | Z39: 1.3335748 | AA39: 0.61599259 | AB39: 0.18
A40: 43363 | B40: 148.6 | C40: 1.05 | D40: 4.1599116 | E40: 8.4692301 | F40: 8.931491 | G40: 9.1623816 | H40: 8.6374087 | I40: 8.6621735 | J40: 7.3362416 | K40: 7.0201258 | L40: 7.2973645 | M40: 7.1633817 | N40: 0.97 | O40: 1.38 | P40: 4.9833645 | Q40: 5.0178119 | R40: 4.8005498 | S40: 4.007032 | T40: 4.3274557 | U40: 4.549048 | V40: 3.33 | W40: -0.25 | X40: -1.8190846 | Y40: 0.70802396 | Z40: 1.9397302 | AA40: 0.84115676 | AB40: 0.07
A41: 43371 | B41: 146.49 | C41: 0.63 | D41: 2.9347487 | E41: 6.5586993 | F41: 7.23559 | G41: 7.5474671 | H41: 7.284139 | I41: 7.4036909 | J41: 5.9815877 | K41: 5.9061723 | L41: 6.1303026 | M41: 6.0053184 | N41: 0.51 | O41: 0.8 | P41: 4.3556661 | Q41: 4.5660644 | R41: 4.6969782 | S41: 4.0784648 | T41: 4.9629399 | U41: 4.7553583 | V41: 2.9 | W41: 0.02 | X41: -1.8074274 | Y41: 0.59822404 | Z41: 1.7727856 | AA41: 0.79464784 | AB41: 0.04
A42: 43377 | B42: 144.59 | C42: 0.45 | D42: 1.9735371 | E42: 5.2780589 | F42: 5.9258419 | G42: 6.2084417 | H42: 6.0145646 | I42: 6.2027441 | J42: 4.9807414 | K42: 4.9211522 | L42: 5.0571868 | M42: 5.2120993 | N42: 0.32 | O42: 0.41 | P42: 3.5081874 | Q42: 3.7702268 | R42: 4.0126253 | S42: 3.4398939 | T42: 4.5424265 | V42: 2.26 | W42: -0.05 | X42: -2.0474924 | Y42: 0.35649567 | Z42: 1.5108625 | AA42: 0.66678731 | AB42: 0.01
A43: 43384 | B43: 145.65 | C43: 0.38 | D43: 2.2195514 | E43: 5.6334821 | F43: 6.2166402 | G43: 6.4985306 | H43: 6.405697 | I43: 5.8679858 | J43: 5.4320655 | K43: 5.4452936 | L43: 5.544745 | M43: 5.4545627 | N43: 0.21 | O43: 0.52 | P43: 3.7990868 | Q43: 4.0735489 | R43: 4.2729748 | S43: 3.613849 | T43: 4.6707791 | V43: 2.43 | W43: -0.34 | X43: -2.1425039 | Y43: 0.32888132 | Z43: 1.5109415 | AA43: 0.81304217 | AB43: 0.07
A44: 43391 | B44: 145.49 | C44: 0.37 | D44: 2.0775907 | E44: 5.3855132 | F44: 5.9686939 | G44: 6.2380549 | H44: 6.1034381 | I44: 5.4896327 | J44: 5.0334319 | K44: 5.0511581 | L44: 5.2635012 | M44: 5.3409341 | N44: 0.29 | O44: 0.62 | P44: 4.1248748 | Q44: 4.7177659 | R44: 2.899475 | S44: 4.179266 | T44: 5.0680019 | V44: 2.49 | W44: -0.15 | X44: -2.1130572 | Y44: 0.71121671 | Z44: 1.726702 | AA44: 0.29952134 | AB44: 0.12
...

Sheet 静力水准
B2: 部位 | C2: 1号坝段 | D2: 2号坝段 | E2: 3号坝段 | F2: 4号坝段 | G2: 4号坝段 | H2: 5号坝段 | I2: 5号坝段 | J2: 5号坝段 | K2: 6号坝段 | L2: 7号坝段 | M2: 8号坝段 | N2: 9号坝段 | O2: 10号坝段 | P2: 3号坝段 | Q2: 4号坝段 | R2: 5号坝段 | S2: 6号坝段 | T2: 7号坝段
B3: 平面位置(m) | C3: 坝左0+201.000 | D3: 坝左0+150.000 | E3: 坝左0+090.000 | F3: 坝左0+037.500 | G3: 坝左0+022.500 | H3: 坝右0+022.000 | I3: 坝右0+023.000 | J3: 坝右0+037.500 | K3: 坝右0+090.000 | L3: 坝右0+150.000 | M3: 坝右0+210.000 | N3: 坝右0+270.000 | O3: 坝右0+323.000 | P3: 坝左0+109.700 | Q3: 坝左0+030.000 | R3: 坝右0+030.000 | S3: 坝右0+090.000 | T3: 坝右0+176.500
B4: 高程(m) | C4: 153 | P4: 88
B5: 埋设时间 | C5: 43222 | P5: 43225
B6: 仪器编号 | C6: TC1-1 | D6: TC1-2 | E6: TC1-3 | F6: TC1-4 | G6: TC1-5 | H6: TC1-6 | I6: TC1-6′ | J6: TC1-7 | K6: TC1-8 | L6: TC1-9 | M6: TC1-10 | N6: TC1-11 | O6: TC1-12 | P6: TC3-1 | Q6: TC3-2 | R6: TC3-3 | S6: TC3-4 | T6: TC3-5
B7: 观测时间 | C7: 位移mm | D7: 位移mm | E7: 位移mm | F7: 位移mm | G7: 位移mm | H7: 位移mm | I7: 位移mm | J7: 位移mm | K7: 位移mm | L7: 位移mm | M7: 位移mm | N7: 位移mm | O7: 位移mm | P7: 位移mm | Q7: 位移mm | R7: 位移mm | S7: 位移mm | T7: 位移mm
B8: 43256 | C8: 0 | D8: 0 | E8: 0 | F8: 0 | G8: 0 | H8: 0 | I8: 0 | J8: 0 | K8: 0 | L8: 0 | M8: 0 | N8: 0 | O8: 0 | P8: 0 | Q8: 0 | R8: 0 | S8: 0 | T8: 0
B9: 43258 | C9: 0 | D9: -0.340605 | E9: -0.3912408 | F9: -0.203454 | G9: 0.2501968 | H9: 0.2117168 | I9: 0.1956684 | J9: 0.138938 | K9: 0.4329808 | L9: 0.1902552 | M9: 0.2233318 | N9: 0.2019758 | O9: 0 | P9: 0 | Q9: -0.0743152 | R9: -0.3956082 | S9: -0.1254661 | T9: -0.0695168
B10: 43262 | C10: -0.16 | D10: 0.002215 | E10: -0.2276296 | F10: 0.2468792 | G10: 0.8349616 | H10: 0.9857 | I10: 0.3860684 | J10: 0.0627366 | K10: 0.327833 | L10: 0.5599786 | M10: -0.1380764 | N10: 0.480058 | O10: 0.01 | P10: -0.02 | Q10: -0.2943336 | R10: -0.6281951 | S10: 0.2704619 | T10: -0.1252168
B11: 43263 | C11: -0.21 | D11: -0.029067 | E11: -0.1364538 | F11: -0.138725 | G11: 0.511111 | H11: 0.6638678 | I11: 0.1237562 | J11: 0.1852004 | K11: 0.3511624 | L11: 0.4685656 | M11: -0.305573 | N11: -0.4848956 | O11: 0.01 | P11: 0.2 | Q11: -0.0412334 | R11: -0.2816689 | S11: 0.6611598 | T11: 0.2817586
B12: 43265 | C12: -0.15 | D12: 0.035434 | E12: 0.121062 | F12: -0.2257368 | G12: -0.0986872 | H12: 0.5311388 | I12: 0.1591866 | J12: 0.3571048 | K12: 0.2794624 | L12: 0.6843868 | M12: -0.408847 | N12: -0.3957766 | O12: 0.01 | P12: 0.2 | Q12: -0.140951 | R12: -0.2032285 | S12: 0.1934036 | T12: 0.4396474
B13: 43267 | C13: -0.2 | D13: -0.192589 | E13: 0.3928948 | F13: 0.1549152 | G13: 0.315834 | H13: 0.9628008 | I13: 0.2852854 | J13: 0.5320416 | K13: 0.3552648 | L13: 0.4835764 | M13: -0.4144838 | N13: -0.2567222 | O13: 0.04 | P13: 0.18 | Q13: -0.2494474 | R13: -0.1104969 | S13: -0.0096003 | T13: 0.5782854
B14: 43269 | C14: -0.19 | D14: 0.768608 | E14: 0.9579338 | F14: 0.7069262 | G14: 0.7680658 | H14: 0.3834974 | I14: 0.1158964 | J14: 0.7109136 | K14: 0.5794724 | L14: 0.0274088 | M14: -0.1974118 | N14: -0.6175616 | O14: 0.02 | P14: 0.3 | Q14: -0.0955712 | R14: 0.0144858 | S14: 0.168745 | T14: 0.6360672
B15: 43272 | C15: -0.18 | D15: 0.061333 | E15: 0.268317 | F15: 0.2877766 | G15: 0.2434142 | H15: 0.3724926 | I15: 0.2071248 | J15: 0.5227668 | K15: 0.5882712 | L15: -0.0530552 | M15: 0.5385232 | N15: 0.1065922 | O15: -0.02 | P15: 0.29 | Q15: -0.2162982 | R15: 0.1121888 | S15: 0.3248762 | T15: 0.5850378
B16: 43274 | C16: -0.13 | D16: -0.546845 | E16: 0.0543398 | F16: -0.149341 | G16: 0.3217382 | H16: 0.8702854 | I16: 0.5927016 | J16: 0.2630568 | K16: 0.488806 | L16: -0.4258308 | M16: 0.5795038 | N16: 0.4111812 | O16: -0.03 | P16: 0.31 | Q16: -0.0492934 | R16: 0.1557136 | S16: 0.1982911 | T16: 0.346641
B17: 43277 | C17: -0.16 | D17: -0.320203 | E17: 0.2493704 | F17: -0.105106 | G17: -0.036424 | H17: 0.2531296 | I17: 0.0392178 | J17: 0.317137 | K17: -0.4097659 | L17: -0.7304306 | M17: 0.1083412 | N17: -0.7485902 | O17: 0.01 | P17: 0.31 | Q17: 0.2035318 | R17: 0.3236653 | S17: 0.401599 | T17: 0.3817846
B18: 43279 | C18: -0.15 | D18: 0.067822 | E18: 0.3765972 | F18: 0.1766296 | G18: 0.4661488 | H18: 0.6642936 | I18: 0.9305352 | J18: 2.1118686 | K18: -0.9785698 | L18: -0.1220966 | M18: 0.2234458 | N18: -2.4196656 | O18: 0.04 | P18: 0.3 | Q18: 0.2709286 | R18: 0.4973541 | S18: -0.0987023 | T18: 0.5037334
B19: 43281 | C19: -0.13 | D19: 0.121662 | E19: 0.4260974 | F19: 0.4164438 | G19: 0.596681 | H19: 0.7818626 | I19: 0.3324526 | J19: -0.2574198 | K19: -0.2838937 | L19: -0.2728626 | M19: 0.1707304 | N19: -0.115664 | O19: 0.06 | P19: 0.32 | Q19: 0.3683254 | R19: 0.7010429 | S19: 0.1097081 | T19: 0.6556822
... B39: 43356 | C39: -0.13 | D39: -0.3609669 | E39: -3.4741819 | F39: 0.8916141 | G39: 0.1035097 | H39: 0.8770713 | I39: 1.7819718 | J39: 1.5833638 | K39: 0.7952647 | L39: 2.0730782 | M39: 0.967942 | N39: -8.1850349 | O39: 0.2 | P39: 0.45 | Q39: 1.9009548 | R39: 3.1213917 | S39: 0.4734873 | T39: 2.014099
B40: 43363 | C40: -0.18 | D40: -0.9007709 | E40: -4.3415969 | F40: -1.4167837 | G40: -1.0600609 | H40: -0.6550109 | I40: 1.6780384 | J40: 1.445599 | K40: -0.3360253 | L40: 2.1389294 | M40: 0.005368 | N40: -7.8736893 | O40: 0.08 | P40: 0.44 | Q40: 1.7480255 | T40: 1.4057386
B41: 43371 | C41: 0.03 | D41: -0.2941671 | E41: -3.6349061 | F41: 0.9267715 | G41: 0.0683455 | H41: 1.3058127 | I41: 1.9029708 | J41: 1.519619 | K41: 2.002944 | L41: 1.4569754 | M41: 1.9211152 | N41: -8.7406372 | O41: 0.08 | P41: 0.47 | Q41: 1.9261904 | T41: 1.2748526
B42: 43377 | C42: 0.01 | D42: -0.3134225 | E42: -3.5797407 | F42: 0.3274109 | G42: -0.0879151 | H42: 1.2029841 | I42: 1.8815168 | J42: 1.5985306 | K42: 0.7072509 | L42: 1.8382582 | M42: 1.01707 | N42: -8.6661097 | O42: 0.19 | P42: 0.46 | Q42: 1.7568943 | T42: 1.631099
B43: 43384 | C43: 0.08 | D43: -0.152281 | E43: -3.4949404 | F43: 1.0204312 | G43: 0.337294 | H43: 1.7489808 | I43: 1.8838742 | J43: 1.4578634 | K43: 1.769557 | L43: 1.440045 | M43: 1.6895624 | N43: -9.2538051 | O43: 0.15 | P43: 0.47 | Q43: 1.6965744 | T43: 1.5332926
B44: 43391 | C44: 0.08 | D44: -0.1762819 | E44: -3.4556357 | F44: 1.2523603 | G44: 0.7396495 | H44: 2.2349879 | I44: 2.0971218 | J44: 1.6103446 | K44: 1.249465 | L44: 1.4685222 | M44: 1.3067086 | N44: -9.1119151 | O44: 0.15 | P44: 0.48 | Q44: 1.6993989 | T44: 1.6407614
B45: 43398 | C45: 0 | D45: -0.4511347 | E45: -3.8492365 | F45: -0.1834993 | G45: -0.2630909 | H45: 1.2225823 | I45: 1.9491528 | J45: 1.6747566 | K45: 1.457276 | L45: 1.684865 | M45: 0.464918 | N45: -8.6889475 | O45: 0.17 | P45: 0.48 | Q45: 1.7682837 | T45: 1.4354862
B46: 43411 | C46: 0.2 | D46: -0.0846186 | E46: -3.5625252 | F46: 1.9455812 | G46: 1.7186984 | H46: 2.9180404 | I46: 2.7078768 | J46: 1.8446106 | K46: 3.1594713 | L46: 1.2891578 | M46: 2.275277 | N46: -9.7944737 | O46: 0.14 | P46: 0.49 | Q46: 1.7352307 | T46: 1.5444318
B47: 43418 | C47: 0.2 | D47: -0.1287004 | E47: -3.6780288 | F47: 1.2668916 | G47: 0.7916716 | H47: 2.2933892 | I47: 1.8780318 | J47: 1.411971 | K47: 2.7216143 | L47: 1.2197214 | M47: 1.4382684 | N47: -9.4652212 | O47: 0.15 | P47: 0.5 | Q47: 1.7165287 | T47: 1.4170894
B48: 43431 | C48: 0.2 | D48: 0.6223099 | E48: -2.8217107 | F48: 2.5291641 | G48: 2.2310885 | H48: 3.5857129 | I48: 2.4703628 | J48: 1.8091102 | K48: 4.2150954 | L48: 1.470045 | M48: 2.3093642 | N48: -9.6693397 | O48: 0.18 | P48: 0.49 | Q48: 1.6749565 | T48: 1.6153182
B49: 43440 | C49: 0.22 | D49: 0.0824299 | E49: -3.5080221 | F49: 1.8786759 | G49: 1.4915363 | H49: 2.9090951 | I49: 1.9111772 | J49: 1.0633514 | K49: 3.0666718 | L49: 0.9294698 | M49: 2.7590844 | N49: -9.7573792 | O49: 0.17 | P49: 0.5 | Q49: 1.5988505 | T49: 1.4909294
B50: 43449 | C50: 0.2 | D50: -0.2672525 | E50: -3.6486759 | F50: 2.5143777 | G50: 2.5837545 | H50: 3.4651973 | I50: 3.298856 | J50: 2.2753778 | K50: 2.9952271 | L50: 1.2836302 | M50: 3.0970676 | N50: -9.8387304 | O50: 0.1 | P50: 0.53 | Q50: 1.6288505 | T50: 1.6833774
B51: 43459 | C51: 0.22 | D51: 0.0854516 | E51: -3.2225124 | F51: 2.271576 | G51: 2.2855156 | H51: 3.4602964 | I51: 2.1424004 | J51: 0.9041938 | K51: 3.0481165 | L51: 0.8145058 | M51: 3.0468088 | N51: -9.7692043 | O51: 0.15 | Q51: 1.626026 | T51: 1.5847694
B52: 43470 | C52: 0.23 | D52: -0.0017774 | E52: -3.1915682 | F52: 2.2830254 | G52: 2.5755078 | H52: 3.8174698 | I52: 3.0034818 | J52: 1.7439726 | K52: 2.9981165 | L52: 1.5165078 | M52: 1.89399 | N52: -8.8960392 | O52: 0.18 | P52: 0.53 | Q52: 1.4652491 | R52: 3.1894061 | S52: 0.5415017 | T52: 1.6612254
B53: 43480 | C53: 0.18 | D53: -5.34e-05 | E53: -3.131757 | F53: 1.963733 | G53: 2.3664058 | H53: 3.5779774 | I53: 2.54036 | J53: 1.2030794 | K53: 4.059306 | L53: 1.2647094 | M53: 1.0499378 | N53: -9.523193 | O53: 0.23 | P53: 0.54 | Q53: 2.0380206 | R53: 3.7510326 | S53: 0.8690059 | T53: 2.2304178
B54: 43490 | C54: 0.19 | D54: -0.1478104 | E54: -3.1173264 | F54: 2.9134356 | G54: 2.859268 | H54: 3.9071644 | I54: 2.913692 | J54: 1.7400322 | K54: 4.6094985 | L54: 1.4121278 | M54: 3.8061576 | N54: -9.2290107 | O54: 0.29 | P54: 0.52 | Q54: 1.9242795 | R54: 3.6704929 | S54: 0.736621 | T54: 2.3185884
B55: 43500 | C55: 0.29 | D55: -0.141406 | E55: -2.9179144 | F55: 3.3701268 | G55: 3.4894256 | H55: 4.3750496 | I55: 2.2875616 | J55: 1.1753534 | K55: 4.0996496 | L55: 0.7556126 | M55: 3.2780798 | N55: -9.8459781 | O55: 0.32 | P55: 0.53 | Q55: 1.4271955 | R55: 3.1490663 | S55: 0.4011306 | T55: 1.8623056
B56: 43510 | C56: 0.27 | D56: 0.0113512 | E56: -2.7782158 | F56: 3.8474394 | G56: 3.9134822 | H56: 4.6340266 | I56: 2.7438166 | J56: 1.7709944 | K56: 3.5394455 | L56: 0.9473036 | M56: 3.4155712 | N56: -10.077811 | O56: 0.41 | P56: 0.51 | Q56: 0.6622277 | R56: 2.3857818 | S56: -0.2940284 | T56: 1.1896256
B57: 43521 | C57: 0.07 | D57: -0.3164707 | E57: -3.0020363 | F57: 3.5584873 | G57: 3.5811269 | H57: 4.3823825 | I57: 1.4991192 | J57: 0.4721586 | K57: 3.7803707 | L57: 0.1635986 | M57: 3.098091 | N57: -10.676009 | O57: 0.41 | P57: 0.42 | Q57: 0.4691205 | R57: 2.2087089 | S57: -0.1112617 | T57: 1.141554
B58: 43530 | C58: 0.01 | D58: -0.598981 | E58: -3.3112868 | F58: 2.9688896 | G58: 3.0026344 | H58: 3.9572056 | I58: 2.4941842 | J58: 1.2594316 | K58: 4.4309652 | L58: 1.2544856 | M58: 4.0535972 | N58: -9.5816119 | O58: 0.41 | P58: 0.55 | Q58: -0.3734006 | R58: 1.391713 | S58: -0.695692 | T58: 0.4704668
B59: 43539 | C59: 0.2 | D59: -0.5123646 | E59: -3.1736346 | F59: 3.0147986 | G59: 3.1250406 | H59: 4.1128346 | I59: 2.6977064 | J59: 1.459312 | K59: 5.0169856 | L59: 2.0570628 | M59: 4.5753008 | N59: -9.2827469 | O59: 0.48 | P59: 0.71 | Q59: -0.2789411 | R59: 1.4904881 | S59: -0.4636169 | T59: 0.7039642
B60: 43549 | C60: 0.35 | D60: -0.5532103 | E60: -3.2175621 | F60: 2.8286871 | G60: 3.2204043 | H60: 4.1881347 | I60: 2.6288844 | J60: 1.5568934 | K60: 2.8742198 | L60: 1.6565206 | M60: 2.9310874 | N60: -9.1445313 | O60: 0.52 | P60: 0.8 | Q60: -0.2305104 | R60: 1.5503369 | S60: -0.8961804 | T60: 0.7659048
...

Sheet 水位
A1: 观测时间 | B1: 河水位
B2: 上游 | C2: 下游
A3: 40369 | B3: 51.4
A4: 40379 | B4: 51.5
A5: 40389 | B5: 52.5
A6: 40400 | B6: 55
A7: 40410 | B7: 51.3
A8: 40420 | B8: 52
A9: 40431 | B9: 51.4
A10: 40441 | B10: 51.3
A11: 40451 | B11: 51.5
A12: 40461 | B12: 52.6 | C12: 48.4
A13: 40468.333 | B13: 53 | C13: 48
A14: 40471.333 | B14: 52.5 | C14: 48.2
A15: 40475.333 | B15: 52.3 | C15: 48
A16: 40482.333 | B16: 51.4 | C16: 47.6
A17: 40489.333 | B17: 51.2 | C17: 47.6
A18: 40492.333 | B18: 51.2 | C18: 47.6
A19: 40496.333 | B19: 51 | C19: 47.8
A20: 40502.333 | B20: 51.1 | C20: 47.6
A21: 40509.333 | B21: ＜51.0 | C21: 48
A22: 40513.333 | B22: 51.2 | C22: 47.7
A23: 40516.333 | B23: ＜51.0 | C23: 47.5
A24: 40522.333 | B24: ＜51.0 | C24: 47.4
A25: 40523.333 | B25: ＜51.0 | C25: 46.5
A26: 40530.333 | B26: ＜51.0 | C26: 46.4
A27: 40532.333 | B27: ＜51.0 | C27: 46.2
A28: 40537.333 | B28: ＜51.0 | C28: 46
A29: 40542.333 | B29: ＜51.0 | C29: 46
A30: 40545.333 | B30: ＜51.0 | C30: 46
A31: 40553.333 | B31: ＜51.0 | C31: 46
A32: 40559.333 | B32: ＜51.0 | C32: 46
A33: 40564.333 | B33: ＜51.0 | C33: 45.8
A34: 40570.333 | B34: ＜51.0 | C34: 45.8
... A40: 40612.333 | B40: ＜51.0 | C40: 45.6
A41: 40622.333 | B41: ＜51.0
A42: 40634.333 | B42: 50.8 | C42: 低于标尺水位,无法读数
A43: 40635.333 | B43: 51.8 | C43: 低于标尺水位,无法读数
A44: 40636.333 | B44: 53.3 | C44: 低于标尺水位,无法读数
A45: 40637.333 | B45: 55.1 | C45: 低于标尺水位,无法读数
...

Sheet 倒垂线
B1: 部位 | C1: 库水位（米） | D1: 1号坝段 | F1: 2号坝段 | H1: 3号坝段 | J1: 4号坝段 | L1: 5号坝段 | N1: 6号坝段 | P1: 7号坝段 | R1: 9号坝段 | T1: 10号坝段
B2: 平面位置(m) | D2: 坝上0+000.900 坝左0+199.600 | F2: 坝下0+007.600 坝左0+161.800 | H2: 坝下0+011.200 坝左0+109.600 | J2: 坝下0+004.700 坝左0+046.000 | L2: 坝下0+003.500坝右0+008.300 | N2: 坝下0+002.000坝右0+092.000 | P2: 坝下0+012.500 坝右0+177.650 | R2: 坝下0+006.500 坝右0+257.000 | T2: 坝上0+001.500 坝右0+323.000
B3: 高程(m) | D3: 153 | F3: 120 | H3: 88 | J3: 43 | L3: 43 | N3: 60 | P3: 88 | R3: 120 | T3: 153
B4: 埋设时间 | D4: 40894 | F4: 40628 | H4: 40628 | J4: 43233 | L4: 41834 | N4: 41844 | P4: 40628 | R4: 40628 | T4: 40894
B5: 仪器编号 | D5: IP1 | F5: IP3 | H5: IP5 | J5: IP9 | L5: IP7 | N5: IP8 | P5: IP6 | R5: IP4 | T5: IP2
B6: 观测时间 | D6: 左右岸CH1 | E6: 上下游CH2 | F6: 左右岸CH1 | G6: 上下游CH2 | H6: 左右岸CH1 | I6: 上下游CH2 | J6: 左右岸CH1 | K6: 上下游CH2 | L6: 左右岸CH1 | M6: 上下游CH2 | N6: 左右岸CH1 | O6: 上下游CH2 | P6: 左右岸CH1 | Q6: 上下游CH2 | R6: 左右岸CH1 | S6: 上下游CH2 | T6: 左右岸CH1 | U6: 上下游CH2
B7: 40631.833 | F7: 0 | G7: 0 | H7: 0 | I7: 0 | P7: 0 | Q7: 0 | R7: 0 | S7: 0
B8: 40643.333 | F8: 0.25 | G8: -0.01 | H8: -0.04 | I8: -0.14 | P8: 0.03 | Q8: -0.59 | R8: -0.55 | S8: 4.04
B9: 40650.333 | F9: -0.24 | G9: -0.08 | H9: -0.13 | I9: -0.17 | P9: 0.09 | Q9: -0.63 | R9: -0.47 | S9: 3.64
B10: 40651.333 | F10: -0.23 | G10: -0.09 | H10: -0.07 | I10: -0.22 | P10: 0.08 | Q10: -0.65 | R10: -0.45 | S10: 2.46
B11: 40657.333 | F11: -0.3 | G11: -0.01 | H11: -0.11 | I11: -0.19 | P11: 0.08 | Q11: -0.56 | R11: -0.76 | S11: -0.44
B12: 40658.333 | F12: -0.28 | G12: 0.03 | H12: -0.05 | I12: -0.34 | P12: 0.06 | Q12: -0.72 | R12: -0.7 | S12: -0.5
B13: 40664.333 | F13: 0.35 | G13: 0.12 | H13: -0.12 | I13: -0.24 | P13: 0.01 | Q13: -0.64 | R13: -0.44 | S13: 0.21
B14: 40671.333 | F14: 0.39 | G14: -0.69 | H14: -0.15 | I14: -0.23 | P14: 0.05 | Q14: -0.71 | R14: -0.15 | S14: 3.69
B15: 40679.333 | F15: 0.21 | G15: -1.02 | H15: -0.2 | I15: -0.3 | P15: 0.13 | Q15: -0.7 | R15: 0.56 | S15: 0.48
B16: 40685.333 | F16: 0.19 | G16: -0.95 | H16: -0.22 | I16: -0.35 | P16: 0.32 | Q16: -0.47 | R16: 0.56 | S16: 0.48
B17: 40689.333 | F17: 0.16 | G17: -0.65 | H17: -0.23 | I17: -0.37 | P17: 0.32 | Q17: -0.47 | R17: 2.07 | S17: -0.58
B18: 40696.333 | F18: 0.1 | G18: -0.87 | H18: -0.41 | I18: -0.01 | P18: 0.39 | Q18: 0.19 | R18: 0.5 | S18: -0.23
... B44: 40735.333 | F44: -1.62 | G44: 2.8 | H44: -0.22 | I44: 4.11 | P44: 0.19 | Q44: 3.07 | R44: 1.47 | S44: 8.04
B45: 40743.333 | F45: -1.7 | G45: 3.26 | H45: -0.32 | I45: 4.43 | R45: 1.53 | S45: 8.97
B46: 40744.333 | F46: -1.69 | G46: 3.27 | H46: -0.33 | I46: 4.46 | P46: -0.46 | Q46: 2.82 | R46: 1.59 | S46: 8.91
B47: 40750.333 | F47: -1.8 | G47: 3.47 | H47: -0.43 | I47: 4.53 | P47: -1.12 | Q47: 3.71 | R47: 1.63 | S47: 9.29
B48: 40754.333 | F48: -1.91 | G48: 4.26 | H48: -0.41 | I48: 5.3 | P48: -1.17 | Q48: 4.16 | R48: 1.82 | S48: 10.86
B49: 40755.333 | F49: -1.95 | G49: 4.47 | H49: -0.38 | I49: 5.39 | P49: -1.27 | Q49: 4.4 | R49: 1.81 | S49: 11.97
B50: 40755.583 | F50: -1.95 | G50: 4.47 | H50: -0.38 | I50: 5.39 | P50: -1.27 | Q50: 4.4 | R50: 1.81 | S50: 11.97
B51: 40756.333 | F51: -1.96 | G51: 4.43 | H51: -0.42 | I51: 5.4 | P51: -1.6 | Q51: 4.68 | R51: 1.86 | S51: 12
B52: 40756.583 | F52: -1.96 | G52: 4.43 | H52: -0.42 | I52: 5.4 | P52: -1.6 | Q52: 4.68 | R52: 1.86 | S52: 12
B53: 40757.333 | F53: -1.95 | G53: 4.31 | H53: -0.43 | I53: 5.32 | P53: -1.64 | Q53: 4.78 | R53: 1.8 | S53: 11.78
B54: 40758.333 | F54: -1.93 | G54: 4.21 | H54: -0.43 | I54: 5.2 | P54: -1.76 | Q54: 4.8 | R54: 1.9 | S54: 11.47
B55: 40759.333 | F55: -1.94 | G55: 4.16 | H55: -0.43 | I55: 5.2 | P55: -1.73 | Q55: 4.74 | R55: 1.79 | S55: 11.51
B56: 40760.333 | F56: -1.9 | G56: 4.16 | H56: -0.41 | I56: 5.15 | P56: -1.76 | Q56: 4.7 | R56: 1.78 | S56: 11.4
B57: 40761.333 | F57: -1.91 | G57: 4.11 | H57: -0.44 | I57: 5.15 | P57: -1.89 | Q57: 4.92 | R57: 1.71 | S57: 11.29
... B204: 40896.333 | F204: -2.84 | G204: 7.99 | H204: -0.62 | I204: 8.58 | P204: 0.74 | Q204: 15.21 | R204: 3.6 | S204: 20.55
B205: 40897.333 | D205: 0 | E205: 0 | F205: -2.83 | G205: 7.97 | H205: -0.59 | I205: 8.61 | P205: 0.75 | Q205: 15.26 | R205: 3.6 | S205: 20.6 | T205: 0 | U205: 0
B206: 40898.333 | D206: 0 | E206: -0.03 | F206: -2.82 | G206: 7.99 | H206: -0.62 | I206: 8.62 | P206: 0.68 | Q206: 15.27 | R206: 3.52 | S206: 20.6 | T206: -0.01 | U206: 0.01
B207: 40899.333 | D207: 0.02 | E207: -0.08 | F207: -2.81 | G207: 7.94 | H207: -0.62 | I207: 8.53 | P207: 0.73 | Q207: 15.56 | R207: 3.53 | S207: 20.56 | T207: -0.03 | U207: 0
B208: 40900.333 | D208: 0.08 | E208: -0.04 | F208: -2.82 | G208: 7.99 | H208: -0.58 | I208: 8.5 | P208: 0.96 | Q208: 15.68 | R208: 3.55 | S208: 20.58 | T208: -0.03 | U208: -0.03
B209: 40901.333 | D209: 0.07 | E209: -0.04 | F209: -2.62 | G209: 7.78 | H209: -0.58 | I209: 8.5 | P209: 0.89 | Q209: 15.52 | R209: 3.45 | S209: 20.65 | T209: -0.03 | U209: -0.02
B210: 40902.333 | D210: 0.18 | E210: -0.05 | F210: -2.61 | G210: 7.79 | H210: -0.6 | I210: 8.55 | P210: 0.99 | Q210: 15.44 | R210: 3.46 | S210: 20.63 | T210: -0.04 | U210: -0.02
B211: 40903.333 | D211: 0.19 | E211: -0.13 | F211: -2.63 | G211: 7.86 | H211: -0.61 | I211: 8.43 | P211: 0.95 | Q211: 15.49 | R211: 3.48 | S211: 20.7 | T211: -0.04 | U211: -0.03
...
